Workbook

Sheet EOI
A1: start | B1: end | C1: Implementing_Partner_Support_Organization | D1: What is the name of your business/Enterprise? | E1: Please provide a brief description of what your business / enterprise provides. | F1: Is your business/enterprise formally registered with URSB? | G1: If yes, which kind of registration | H1: Does your business/enterprise have a Tax Identification Number? | I1: If yes, provide the Tin Number | J1: Upload a copy of your Business/Company's URA Certificate of Registration. | K1: Upload a copy of your Business/Company's URA Certificate of Registration._URL | L1: Does the business have a NSSF Business / Employer Number? | M1: Please provide your Company/Business NSSF number | N1: In which Region is your Enterprise located? | O1: In which district is your Enterprise/Business located? | P1: In which Subcounty of the district is your Enterprise/Business located? | Q1: In which Parish of the Subcounty is your Enterprise/Business located? | R1: what sector is your Enterprise/Business operating? | S1: Please specify the sector | T1: How many founders does your Enterprise/Business have? | U1: How many of the Enterprise/Business founders are female? | V1: How many full-time staff do you have? | W1: How many part-time employees do you have? | X1: Provide a list and a brief description about theproduct(s) or service(s) that your business provide | Y1: What problem is your business trying to solve? | Z1: How many suppliers or supplier categories do you have? | AA1: How many people do your suppliers employ? | AB1: _id | AC1: Please explain your business model. | AD1: How much revenue (in UGX) has your Business generated in the last two years (24 months)? | AE1: Have you taken any investments or subsidies yet? | AF1: How many investments or subsidies have you (business) taken? | AG1: Have you participated in any incubator, accelerator or enterprise development program before? | AH1: Please tell us more about it. We would like to know who was running it, what it was offering, what you received, the impact you created, etc | AI1: How much funding (in UGX) would you need to facilitate your business growth plan over the next 1 year? | AJ1: With the financing and technical support provided from the 10X Digital Economy, what growth milestones do you seek to achieve? | AK1: Why do you believe that your business is well positioned to grow and reach more customers? | AL1: Is there any other information about your company that you feel we should know about? | AM1: Which other information about your Enterprise/business should we know about? | AN1: Are you affiliated to anyone working at UNCDF, Refactory, WITU and Outbox? | AO1: Please describe the nature of your relationship with the person at UNCDF, Refactory, WITU and Outbox? | AP1: Do you have a personal,professional or family relationship to anyone working at the following Hubs and organisations; Mkazipreneur, Challenges Uganda, DFCU Foundation, Excel Hort, Finfing XY, MUBS EIIC, PEDN, Stanbic Incubator, Mastercard Foundation, UNCDF, Women In Technology, Refactory & Outbox Uganda Limited.? | AQ1: Please describe the nature of your relationship with the person in any of the above Hubs and organisation? | AR1: Are you or anyone in your business a politically exposed person? | AS1: What is (are) the name of the person(s), the public office (s) held and the role(s) of the staff in your business who are politically exposed? | AT1: What convinced you to apply to the 10X Digital Economy Program? | AU1: How did you hear about to the 10X Digital Economy Program? | AV1: On a scale of 1 - 5, how difficult/easy did you find the expression of interest form? | AW1: Please enter the reason for selecting the option above. | AX1: Do you accept the terms and conditions for participating in the 10X Digital Economy Program? | AY1: Thank you so much for you time and for filling this 10X Digital Economy Expression of Interest Form. | AZ1: Please include all your feedback of the tool here | BA1: Consent/Data Release Form | BB1: Please enter your name | BC1: What is your position / title / role in the company? | BD1: Please provide your primary mobile number (the person filling in the application). | BE1: Please provide the email address of the person filling in the application | BF1: Does ${business_name} have any parent company or subsidiaries? | BG1: Does ${business_name} have any parent company or subsidiaries?/Yes, the company has a parent company. | BH1: Does ${business_name} have any parent company or subsidiaries?/Yes, the company has a subsidiary (subsidiaries). | BI1: Does ${business_name} have any parent company or subsidiaries?/No | BJ1: Please list the parent company below. | BK1: How many subsidiaries does your company have? | BL1: When was your company legally registered with URSB? | BM1: Please upload your certificate of registration | BN1: Please upload your certificate of registration_URL | BO1: Upload a copy of your Company's Memorandum and Articles of Association. | BP1: Upload a copy of your Company's Memorandum and Articles of Association._URL | BQ1: What is your company's Tax Identification Number? | BR1: Please upload Form 20 / Form 7 of your Company Registration Form that evidences the Company Directors | BS1: Please upload Form 20 / Form 7 of your Company Registration Form that evidences the Company Directors_URL | BT1: _id | BU1: _uuid | BV1: _submission_time | BW1: _validation_status | BX1: _notes | BY1: _status | BZ1: _submitted_by | CA1: __version__ | CB1: _tags | CC1: _index | CD1: Breakdown | CE1: Test | CF1: ESO | CG1: What is the name of your business/Enterprise?_f | CH1: _submission__id | CI1: founder_number | CJ1: Please enter the first name of Founder #${founder_number}. | CK1: Please enter ${first_name_f}'s last name. | CL1: Please enter ${first_name_f}'s date of birth. | CM1: Age | CN1: Please select ${first_name_f}'s gender. | CO1: What percentage of shares does ${first_name_f} hold? | CP1: What is ${first_name_f}'s Nationality. | CQ1: Is ${first_name_f} a person with disabilities? | CR1: Please select the disability that ${first_name_f} has from the options below. | CS1: Please select the disability that ${first_name_f} has from the options below./Visual disability | CT1: Please select the disability that ${first_name_f} has from the options below./Mental disability | CU1: Please specify the disability. | CV1: What is ${first_name_f}'s citizenship? | CW1: If Refugee, which country? | CX1: What is ${first_name_f}'s district of residence? | CY1: What is ${first_name_f}'s Subcounty of residence? | CZ1: What is ${first_name_f}'s parish of residence? | DA1: What is ${first_name_f}'s village of residence? | DB1: What is ${first_name_f}'s Mobile number? | DC1: Please enter ${first_name_f}'s valid email address. | DD1: Is ${first_name_f} actively working in the business? | DE1: What is ${first_name_f}'s monthly gross salary? (In Uganda Shillings) | DF1: Please upload a copy of the National ID front page for ${first_name_f}. | DG1: Please upload a copy of the National ID front page for ${first_name_f}._URL | DH1: _index_f | DI1: _parent_table_name | DJ1: _parent_index | DK1: _submission__id.1 | DL1: _submission__uuid | DM1: _submission__submission_time | DN1: _submission__validation_status | DO1: _submission__notes | DP1: _submission__status | DQ1: _submission__submitted_by | DR1: _submission___version__ | DS1: _submission__tags | DT1: ESO_ft | DU1: What is the name of your business/Enterprise?_ft | DV1: _submission__id_ft | DW1: fte_number | DX1: Please enter the first name of Full Time Employee #${fte_number}. | DY1: Is ${first_name_fte} a founder? | DZ1: Please enter ${first_name_fte}'s last name. | EA1: Please enter ${first_name_fte}'s Date of Birth. | EB1: Please select ${first_name_fte}'s Gender. | EC1: What is the role of ${first_name_fte} in the Business/Enterprise? | ED1: What is the monthly gross salary or stipend (In Uganda Shillings) for ${first_name_fte}. | EE1: Is ${first_name_fte} a person with disabilities? | EF1: Please specify the disability._ft | EG1: What is ${first_name_fte}'s citizenship? | EH1: If refugee, name the country | EI1: What is ${first_name_fte}'s home district? | EJ1: What is ${first_name_fte}'s subcounty? | EK1: What is ${first_name_fte}'s Parish? | EL1: What is ${first_name_fte}'s Village? | EM1: What is ${first_name_fte}'s primary phone number? | EN1: What is ${first_name_fte}'s primary email address? | EO1: What is ${first_name_fte}'s highest level of education? | EP1: What is ${first_name_fte}'s National Identification Number (NIN) as shown on the National ID? | EQ1: What is ${first_name_fte}'s subcounty?.1 | ER1: What is ${first_name_fte}'s Parish?.1 | ES1: _index_ft | ET1: _parent_table_name_ft | EU1: _parent_index_ft | EV1: _submission__id.1_ft | EW1: _submission__uuid_ft | EX1: _submission__submission_time_ft | EY1: _submission__validation_status_ft | EZ1: _submission__notes_ft | FA1: _submission__status_ft | FB1: _submission__submitted_by_ft | FC1: _submission___version___ft | FD1: _submission__tags_ft | FE1: ESO_pt | FF1: What is the name of your business/Enterprise?_pt | FG1: _submission__id_pt | FH1: pte_number | FI1: Please enter the first name of Part Time Employee #${pte_number}. | FJ1: Please enter ${first_name_pte}'s last name. | FK1: Please enter ${first_name_pte}'s Date of Birth. | FL1: Please select ${first_name_pte}'s Gender. | FM1: What is the role of ${first_name_pte} in the company? | FN1: What is the monthly gross salary or stipend (In Uganda Shillings) for ${first_name_pte}. | FO1: Is ${first_name_pte} a person with disabilities? | FP1: Please specify the disability._pt | FQ1: What is ${first_name_pte}'s citizenship? | FR1: If Refugee, which country?_pt | FS1: What is ${first_name_pte}'s home district? | FT1: What is ${first_name_pte}'s subcounty? | FU1: What is ${first_name_pte}'s Parish? | FV1: What is ${first_name_pte}'s Village? | FW1: What is ${first_name_pte}'s primary phone number? | FX1: What is ${first_name_pte}'s primary email address? | FY1: What is ${first_name_pte}'s National Identification Number (NIN) as shown on the National ID? | FZ1: _index_pt | GA1: _parent_table_name_pt | GB1: _parent_index_pt | GC1: _submission__id.1_pt | GD1: _submission__uuid_pt | GE1: _submission__submission_time_pt | GF1: _submission__validation_status_pt | GG1: _submission__notes_pt | GH1: _submission__status_pt | GI1: _submission__submitted_by_pt | GJ1: _submission___version___pt | GK1: category | GL1: Age | GM1: Age
A2: 0.021476852 | B2: 45965 | C2: Stanbic Bank Incubator | D2: Prime Classy Perfumes and Beauty Inn | E2: Authentic perfumes, scent oil, automatic air freshener, watches and smart watches, tab speakershand bags, tabs and kids tabs, Victoria secret and bath and body products branded Lotions and creamsand pedicure | F2: No | H2: Yes | I2: 1010807824 | L2: No | N2: Central | O2: Mubende | P2: West division | Q2: Katogo ward | R2: fashion and design | T2: 1 | U2: 1 | V2: 1 | W2: 0 | X2: Authentic perfumes, branded products like Victoria secret and bath and body works, branded Lotions and creams, all types of air freshener, scent oils, branded bags like hand books, kids bags, rechargeable bags, table speaker, smart watches and non smart watches, tabs and kids tabs, shoes , pedicure etc | Y2: It's helps me to development | Z2: 3 | AA2: 20 | AB2: 597810443 | AC2: Charges depends on the product sold but ranges from 5000- 1000000 because the highest expensive product is at that00 | AD2: 4500000 | AE2: No | AG2: No | AI2: 10000000 | AJ2: Enlarging my business | AK2: My business is in the middle of town so the targeted customers are available and prices are friendly and it has a full time attendant | AL2: No | AN2: No | AP2: No | AR2: No | AT2: Learning champion convinced me | AU2: Through learning champion | AV2: 4 - Easy | AW2: Because I was able to interpret the questions asked and replied them | AX2: Yes | AZ2: For sure am loving more more 10x DIGITAL EXPRESSION the tool was easy to fill and the questions were easy to understand. Thanks | BT2: 597810443 | BU2: e95a4725-3b3b-4838-8c7c-7cc00f8e23f4 | BV2: 45965.404 | BY2: submitted_via_web | CA2: vCJgLk2yV8oivMfbcbCpCF | CC2: 431 | CF2: Stanbic Bank Incubator | CG2: Prime Classy Perfumes and Beauty Inn | CH2: 597810443 | CI2: 1 | CJ2: Angella | CK2: Nakatimbo | CL2: 34104 | CN2: Female | CO2: 100 | CP2: Ugandan | CQ2: No | CV2: Ugandan | CX2: Mubende | CY2: West dividion | CZ2: Katogo ward | DA2: Main Street LCI | DB2: 703966762 | DC2: angellanakatimbo1@mail.com | DD2: Yes | DE2: 100000 | DF2: IMG_20251104_113944_522-11_42_13.jpg | DG2: https://kf.kobotoolbox.org/api/v2/assets/a9dTHTe72X7zPceKxVtSxV/data/597810443/attachments/attYsfoQQUzrXmtQ95W4sU9t/ | DH2: 545 | DI2: 10X Digital Economy Expression of interest Form | DJ2: 431 | DK2: 597810443 | DL2: e95a4725-3b3b-4838-8c7c-7cc00f8e23f4 | DM2: 45965.404 | DP2: submitted_via_web | DR2: vCJgLk2yV8oivMfbcbCpCF | DT2: Stanbic Bank Incubator | DU2: Prime Classy Perfumes and Beauty Inn | DV2: 597810443 | DW2: 1 | DX2: Rose | DY2: No | DZ2: Nakiwala | EA2: 38349 | EB2: Female | EC2: Attendant | ED2: 100000 | EE2: No | EG2: Ugandan | EI2: Mubende | EJ2: Kiyuni | EK2: Katente | EL2: Katente | EM2: 747420860 | EO2: S.6 | EP2: CFO403110K3JPE | ES2: 986 | ET2: 10X Digital Economy Expression of interest Form | EU2: 431 | EV2: 597810443 | EW2: e95a4725-3b3b-4838-8c7c-7cc00f8e23f4 | EX2: 45965.404 | FA2: submitted_via_web | FC2: vCJgLk2yV8oivMfbcbCpCF | GK2: Unique | GL2: 0 | GM2: 32
A3: 0.041204861 | B3: 45973 | C3: Stanbic Bank Incubator | D3: Poul | E3: My business provides eggs to the community and durks for those interested in.furk keeping | F3: No | H3: No | L3: No | N3: Central | O3: Wakiso | P3: Wakiso subcouty | Q3: Bukasa parish | R3: Agriculture | T3: 2 | U3: 2 | V3: 1 | W3: 1 | X3: My poutry business is a small scale of 15 durks and 10 layers chicken I employee my self on my small business as I plan to grow bigger than this | Y3: My business is trying to solve a problem of space and healthy of my birds | Z3: 2 | AA3: 2 | AB3: 603755911 | AC3: I make money buy selling off the young ones of durks and selling of eggs from the chicken | AD3: 0 | AE3: No | AG3: Yes | AH3: Stanbic incubatormadam penthroughh various ways like record keeping asand financial literacy nit was offering training on how to look after small scale business asand how to grow in businessinah was running it | AI3: 1000000 | AJ3: I want to see myself having a big farm of over 100 birds and hoodrecords | AK3: Because of the knowledge I have got from the 10 x program training | AL3: Yes | AM3: Expansion interms of space | AN3: Yes | AO3: She is one of my menter from our disability flatanity | AP3: Yes | AQ3: She is apwa as my self | AR3: No | AT3: The traings they offerare quite important | AU3: Through my fellow person with disability | AV3: 3 - Neutral | AW3: Reason being am short sighted and some of the fillings like my nini has not been easy and feeling my birthday date | AX3: Yes | AZ3: Am so greatfull for this program thank you Stanbic icubatoe | BT3: 603755911 | BU3: ba22e98b-bc2c-4fcc-9044-15e33a1658bb | BV3: 45973.279 | BY3: submitted_via_web | CA3: vCJgLk2yV8oivMfbcbCpCF | CC3: 516 | CF3: Stanbic Bank Incubator | CG3: Poul | CH3: 603755911 | CI3: 1 | CJ3: Kasagga | CK3: Faith | CL3: 29020 | CN3: Female | CO3: 80 | CP3: Uganda | CQ3: Yes | CR3: Others | CS3: 0 | CT3: 0 | CU3: Albinism | CV3: Ugandan | CX3: Wakiso | CY3: Wakiso subcounty | CZ3: Bukasa | DA3: Muyomba | DB3: 704744329 | DC3: bwanikafath2016@gmail.com | DD3: Yes | DE3: 50000 | DF3: IMG_20251112_090304_484-9_5_58.jpg | DG3: https://kf.kobotoolbox.org/api/v2/assets/a9dTHTe72X7zPceKxVtSxV/data/603755911/attachments/attGzr3pGm4JzMKTTuqa2Rz3/ | DH3: 638 | DI3: 10X Digital Economy Expression of interest Form | DJ3: 516 | DK3: 603755911 | DL3: ba22e98b-bc2c-4fcc-9044-15e33a1658bb | DM3: 45973.279 | DP3: submitted_via_web | DR3: vCJgLk2yV8oivMfbcbCpCF | DT3: Stanbic Bank Incubator | DU3: Poul | DV3: 603755911 | DW3: 1 | DX3: Kasagga | DY3: Yes | EL3: Muyomba | ES3: 1130 | ET3: 10X Digital Economy Expression of interest Form | EU3: 516 | EV3: 603755911 | EW3: ba22e98b-bc2c-4fcc-9044-15e33a1658bb | EX3: 45973.279 | FA3: submitted_via_web | FC3: vCJgLk2yV8oivMfbcbCpCF | FE3: Stanbic Bank Incubator | FF3: Poul | FG3: 603755911 | FH3: 1 | FI3: Kasagga | FJ3: Faith | FK3: 29171 | FL3: Female | FM3: To take care of the nirds | FN3: 50000 | FO3: Yes | FP3: Albinism | FQ3: Ugandan | FS3: Wakiso | FT3: Wakiso subcouty | FU3: Bukasa | FV3: Muyomba | FW3: 704744329 | FX3: bwanikafaith2016@gmail.com | FY3: Cf790521081cll | FZ3: 376 | GA3: 10X Digital Economy Expression of interest Form | GB3: 516 | GC3: 603755911 | GD3: ba22e98b-bc2c-4fcc-9044-15e33a1658bb | GE3: 45973.279 | GH3: submitted_via_web | GJ3: vCJgLk2yV8oivMfbcbCpCF | GK3: Unique | GL3: 46 | GM3: 46
A4: 0.021215278 | B4: 45973 | C4: Stanbic Bank Incubator | D4: Tamutamu weaving and bag collection | E4: My business provides weaved cupmats , millet basket , and I also sell bags for ladies | F4: No | H4: No | L4: No | N4: Central | O4: Kampala | P4: Makerere | Q4: Makerere | R4: fashion and design | T4: 1 | U4: 1 | V4: 1 | W4: 1 | X4: As aiming to equip and develope yourth with disabilities create opportunities using our local cheap materials to change ,we sell cupmats , table mats, baskets by weaving using our local materials of payrus,we buy ladies bag from wholesale and sell them on retail | Y4: Capital to employe many yourth to development their talents , place where to put my business in stable place , accomodation | Z4: 3 | AA4: 8 | AB4: 603928923 | AC4: Small retail business | AD4: 2000000 | AE4: No | AG4: No | AI4: 2500000 | AJ4: Employee more people with impairments, expand the business to local areas to train more young growing yourth who are unemployed | AK4: Because it targets the yourth who are interested in fashion and also old families that want their houses designed with millet baskets, cup marts, | AL4: Yes | AM4: My business specifically employees the young disabled talented youth to be job creators rather than job seekers, looking forward to export our products even abroad | AN4: No | AP4: No | AR4: Yes | AS4: I myself am the guild representative and minister for pwds at Makerere university | AT4: Need to learn more skills in world of business and financial support | AU4: Got a link from a friend and filled it , he told me that it has been empowering pwds to start up Businesses | AV4: 4 - Easy | AW4: It asks what you really want to be , seeks your general knowledge in the business which is my passion | AX4: Yes | AZ4: It's Abit hectic to fill as for a person with visual impairments , also some places doesn't give option of self expression | BT4: 603928923 | BU4: 88bcafa1-8ca4-41c2-b144-aa9c4eb00e4b | BV4: 45973.415 | BY4: submitted_via_web | CA4: vCJgLk2yV8oivMfbcbCpCF | CC4: 525 | CF4: Stanbic Bank Incubator | CG4: Tamutamu weaving and bag collection | CH4: 603928923 | CI4: 1 | CJ4: Akankunda | CK4: Donitah | CL4: 37249 | CN4: Female | CO4: 100 | CP4: Ugandan | CQ4: Yes | CR4: Visual disability | CS4: 1 | CT4: 0 | CV4: Ugandan | CX4: Kampala | CY4: Makerere | CZ4: Makerere | DA4: Makerere | DB4: 791064779 | DC4: donitahakankunda48@gmail.com | DD4: Yes | DE4: 100000 | DH4: 648 | DI4: 10X Digital Economy Expression of interest Form | DJ4: 525 | DK4: 603928923 | DL4: 88bcafa1-8ca4-41c2-b144-aa9c4eb00e4b | DM4: 45973.415 | DP4: submitted_via_web | DR4: vCJgLk2yV8oivMfbcbCpCF | DT4: Stanbic Bank Incubator | DU4: Tamutamu weaving and bag collection | DV4: 603928923 | DW4: 1 | DX4: Akankunda | DY4: Yes | EL4: Kitoma | ES4: 1142 | ET4: 10X Digital Economy Expression of interest Form | EU4: 525 | EV4: 603928923 | EW4: 88bcafa1-8ca4-41c2-b144-aa9c4eb00e4b | EX4: 45973.415 | FA4: submitted_via_web | FC4: vCJgLk2yV8oivMfbcbCpCF | FE4: Stanbic Bank Incubator | FF4: Tamutamu weaving and bag collection | FG4: 603928923 | FH4: 1 | FI4: Joy | FJ4: Ndayishimye | FK4: 37605 | FL4: Female | FM4: Selling products | FN4: 100000 | FO4: No | FQ4: Ugandan | FS4: Kisoro | FT4: Nyarusiza | FU4: Gitenderi | FV4: Kabande | FW4: 779188559 | FX4: jndayishimye2@gmail.com | FY4: CF0201810EFFGE | FZ4: 377 | GA4: 10X Digital Economy Expression of interest Form | GB4: 525 | GC4: 603928923 | GD4: 88bcafa1-8ca4-41c2-b144-aa9c4eb00e4b | GE4: 45973.415 | GH4: submitted_via_web | GJ4: vCJgLk2yV8oivMfbcbCpCF | GK4: Unique | GL4: 28 | GM4: 24
A5: 0.012311343 | B5: 45973 | C5: Stanbic Bank Incubator | D5: Gabriel fast foods 7 | E5: Provides pasties and fast foods to the community | F5: No | H5: No | L5: No | N5: Central | O5: Wakiso | P5: Nsangi | Q5: Kasenge ward | R5: Others | S5: Bakery | T5: 1 | U5: 1 | V5: 1 | W5: 0 | X5: Daddies, Cookies, Doughnuts, Bread and bans,scones, samosas, chapati and many pastries in all types | Y5: Working from home and limited capital | Z5: 1 | AA5: 2 | AB5: 603971564 | AC5: I make money through supplying cakes to friends on parties, satisfying customers orders like bread. I make different types of pastries to attract more customers at an affordable price to also finish up my daily production and have profit at the end without making loses that I cannot weigh in my micro business | AD5: 0 | AE5: No | AG5: Yes | AH5: Stanbic incubator, teaching about business skills to grow micro businesses to another level of growth which taught me more of business success | AI5: 30000000 | AJ5: Financial support | AK5: Because I will employ many youth and reduce on unemployment problems in my community and also pay revenue to support government services for my country's development | AL5: Yes | AM5: I want to start working on a medium scale and know how to register my business | AN5: Yes | AO5: Business expert lecturer | AP5: Yes | AQ5: Teacher | AR5: No | AT5: I listened to business growth Ideas and also wanted to grow mine | AU5: From Amodo Doreen | AV5: 5 - Very easy | AW5: Because all the questions were clear and understandable, related to my business journey for growth | AX5: Yes | AZ5: Am so grateful for having been granted such an opportunity | BT5: 603971564 | BU5: 64c0ea74-94cc-492c-b5e8-6af324b897d5 | BV5: 45973.444 | BY5: submitted_via_web | CA5: vCJgLk2yV8oivMfbcbCpCF | CC5: 528 | CF5: Stanbic Bank Incubator | CG5: Gabriel fast foods 7 | CH5: 603971564 | CI5: 1 | CJ5: Nakkazi | CK5: Gloria | CL5: 37876 | CN5: Female | CO5: 70 | CP5: Uganda | CQ5: No | CV5: Ugandan | CX5: Wakiso | CY5: Nsangi | CZ5: Kasenge | DA5: Mugongo A | DB5: 771936183 | DC5: gloriavocal9@gmail.com | DD5: No | DH5: 651 | DI5: 10X Digital Economy Expression of interest Form | DJ5: 528 | DK5: 603971564 | DL5: 64c0ea74-94cc-492c-b5e8-6af324b897d5 | DM5: 45973.444 | DP5: submitted_via_web | DR5: vCJgLk2yV8oivMfbcbCpCF | DT5: Stanbic Bank Incubator | DU5: Gabriel fast foods 7 | DV5: 603971564 | DW5: 1 | DX5: Nakkazi Gloria | DY5: Yes | EL5: Mugongo A | ES5: 1145 | ET5: 10X Digital Economy Expression of interest Form | EU5: 528 | EV5: 603971564 | EW5: 64c0ea74-94cc-492c-b5e8-6af324b897d5 | EX5: 45973.444 | FA5: submitted_via_web | FC5: vCJgLk2yV8oivMfbcbCpCF | GK5: Unique | GL5: 31 | GM5: 22
A6: 0.018792824 | B6: 45973 | C6: Stanbic Bank Incubator | D6: Hannah's bakery and sweet snacks | E6: Cakes | F6: No | H6: No | L6: No | N6: Central | O6: Wakiso | P6: Nakabugo | Q6: Nakuwadde | R6: trade and services | T6: 2 | U6: 2 | V6: 1 | W6: 1 | X6: Cakes,chapatis,piza,cookies | Y6: Reducing on the loss | Z6: 5 | AA6: 5 | AB6: 604130561 | AC6: I make cakes from 70k | AD6: 10000 | AE6: No | AG6: Yes | AH6: Managing my business finances and savings for growth | AI6: 10000000 | AJ6: To grow my business bigger | AK6: Because business incubator has taught us more about digital marketing credit | AL6: No | AN6: No | AP6: Yes | AQ6: Liven | AR6: No | AT6: Growing my business and savings for growth and marketing my business online | AU6: Through business incubator | AV6: 3 - Neutral | AW6: It needed mindset | AX6: Yes | AZ6: Thanks for growing my business | BT6: 604130561 | BU6: d2a7a0b5-2591-482d-b0c0-5b3c39489c7d | BV6: 45973.562 | BY6: submitted_via_web | CA6: vCJgLk2yV8oivMfbcbCpCF | CC6: 534 | CF6: Stanbic Bank Incubator | CG6: Hannah's bakery and sweet snacks | CH6: 604130561 | CI6: 2 | CJ6: Nabunnya | CK6: Annnet | CL6: 36615 | CN6: Female | CO6: 50 | CP6: Ugandan | CQ6: No | CV6: Ugandan | CX6: Wakiso | CY6: Nakabugo | CZ6: Nakuwadde | DA6: Nakuwadde | DB6: 741769493 | DC6: annetnabunnya649@gmail.com | DD6: No | DF6: 20251112_160557-16_10_24.heic | DG6: https://kf.kobotoolbox.org/api/v2/assets/a9dTHTe72X7zPceKxVtSxV/data/604130561/attachments/attsxRGdb5ETLgM2kDvHXpFg/ | DH6: 660 | DI6: 10X Digital Economy Expression of interest Form | DJ6: 534 | DK6: 604130561 | DL6: d2a7a0b5-2591-482d-b0c0-5b3c39489c7d | DM6: 45973.562 | DP6: submitted_via_web | DR6: vCJgLk2yV8oivMfbcbCpCF | DT6: Stanbic Bank Incubator | DU6: Hannah's bakery and sweet snacks | DV6: 604130561 | DW6: 1 | DX6: Nabunnya Annet | DY6: Yes | EL6: Nakuwadde | ES6: 1161 | ET6: 10X Digital Economy Expression of interest Form | EU6: 534 | EV6: 604130561 | EW6: d2a7a0b5-2591-482d-b0c0-5b3c39489c7d | EX6: 45973.562 | FA6: submitted_via_web | FC6: vCJgLk2yV8oivMfbcbCpCF | FE6: Stanbic Bank Incubator | FF6: Hannah's bakery and sweet snacks | FG6: 604130561 | FH6: 1 | FI6: Nabunnya | FJ6: Annet | FK6: 36615 | FL6: Female | FM6: Baking cakes | FN6: 200000 | FO6: No | FQ6: Ugandan | FS6: Wakiso | FT6: Nakabugo | FU6: Nakuwadde | FV6: Nakuwadde | FW6: 741769493 | FX6: annetnabunnya649@gmail.com | FY6: CF00012107LL7L | FZ6: 379 | GA6: 10X Digital Economy Expression of interest Form | GB6: 534 | GC6: 604130561 | GD6: d2a7a0b5-2591-482d-b0c0-5b3c39489c7d | GE6: 45973.562 | GH6: submitted_via_web | GJ6: vCJgLk2yV8oivMfbcbCpCF | GK6: Unique | GL6: 23 | GM6: 23
A7: 0.029237269 | B7: 45973 | C7: Stanbic Bank Incubator | D7: Gabriella's beauty saloon | E7: Hairstyling and cosmetics | F7: No | H7: No | L7: No | N7: Central | O7: Wakiso | P7: Nsangi | Q7: Kyengera | R7: fashion and design | T7: 1 | U7: 1 | V7: 1 | W7: 0 | X7: Hairstyling, makeup, wig installation,nail technician | Y7: Low Market | Z7: 1 | AA7: 0 | AB7: 604297815 | AC7: Hairstyling and cosmetics | AD7: 0 | AE7: No | AG7: No | AI7: 4000000 | AJ7: Increase my income and profit. Get more customers and make my business known. Make another branch to earn more | AK7: It is in a good location | AL7: No | AN7: No | AP7: Yes | AQ7: Friend | AR7: No | AT7: To get more business knowledge | AU7: Via Dreams program | AV7: 3 - Neutral | AW7: Too many questions | AX7: Yes | AZ7: Thanks for everything | BT7: 604297815 | BU7: 81e373d2-14b3-4c09-ace4-1d30b8979dc5 | BV7: 45973.697 | BY7: submitted_via_web | CA7: vCJgLk2yV8oivMfbcbCpCF | CC7: 547 | CF7: Stanbic Bank Incubator | CG7: Gabriella's beauty saloon | CH7: 604297815 | CI7: 1 | CJ7: AINEMBABAZI | CK7: SANDRA | CL7: 38658 | CN7: Female | CO7: 100 | CP7: Ugandan | CQ7: No | CV7: Ugandan | CX7: Wakiso | CY7: Nsangi | CZ7: Kyengera | DA7: Masanda | DB7: 769812414 | DC7: camraiseelainesandie@gmail.com | DD7: No | DF7: IMG-20251011-WA0246-18_51_13.jpg | DG7: https://kf.kobotoolbox.org/api/v2/assets/a9dTHTe72X7zPceKxVtSxV/data/604297815/attachments/atthpFwjWVikDEqUBynrbmMv/ | DH7: 673 | DI7: 10X Digital Economy Expression of interest Form | DJ7: 547 | DK7: 604297815 | DL7: 81e373d2-14b3-4c09-ace4-1d30b8979dc5 | DM7: 45973.697 | DP7: submitted_via_web | DR7: vCJgLk2yV8oivMfbcbCpCF | DT7: Stanbic Bank Incubator | DU7: Gabriella's beauty saloon | DV7: 604297815 | DW7: 1 | DX7: Ainembabazi Sandra | DY7: Yes | EL7: Masanda | ES7: 1174 | ET7: 10X Digital Economy Expression of interest Form | EU7: 547 | EV7: 604297815 | EW7: 81e373d2-14b3-4c09-ace4-1d30b8979dc5 | EX7: 45973.697 | FA7: submitted_via_web | FC7: vCJgLk2yV8oivMfbcbCpCF | GK7: Unique | GL7: 21 | GM7: 21
A8: 0.03537963 | B8: 45973 | C8: Stanbic Bank Incubator | D8: Harrietcrafts | E8: Harrietcrafts is a social interprise dealing in making crafts like functional baskets mats verses hut netivities and many others | F8: No | H8: No | L8: No | N8: Central | O8: Wakiso | P8: Busiro | Q8: Wakiso | R8: fashion and design | T8: 1 | U8: 1 | V8: 1 | W8: 0 | X8: It provides mats verses hut netivities and baskets for home use | Y8: It solves diseases from poor sanitation | Z8: 3 | AA8: 5 | AB8: 604370172 | AC8: These are the resources needed to run this social interprise rent for at list 2months 200000total400000 phone for internet and communication at700000 sowing needles at 50000 sisol at100000 bananastem at 100000 bananafibires at 50000 vernish woodglue at1000005litres transport 100000total 1600000 | AD8: 400000 | AE8: No | AG8: Yes | AH8: The stanbic incubator program was runned by mr waguma it was offering capacity building irecieved how to develop financially and to solve unemployment | AI8: 2000000 | AJ8: I expect to employ more workers to make more quality products to expand the business to grow and to increase on the costs of the products | AK8: Due to good quality products made and use of internt for marketing | AL8: No | AN8: No | AP8: No | AR8: No | AT8: I wanted to develop financially to solve unemployment | AU8: Thrugh madam peninah | AV8: 3 - Neutral | AW8: Some questions have been simple and others difficult | AX8: Yes | AZ8: Thank you for your support and for introducing capacity building | BT8: 604370172 | BU8: cc141231-43f2-4fff-b593-2d30d8788b70 | BV8: 45973.769 | BY8: submitted_via_web | CA8: vCJgLk2yV8oivMfbcbCpCF | CC8: 550 | CF8: Stanbic Bank Incubator | CG8: Harrietcrafts | CH8: 604370172 | CI8: 1 | CJ8: Nakijjoba | CK8: Harriet | CL8: 35069 | CN8: Female | CO8: 50 | CP8: Ugandan | CQ8: Yes | CR8: Physical Disability | CS8: 0 | CT8: 0 | CV8: Ugandan | CX8: Wakiso | CY8: Busiro | CZ8: Wakiso | DA8: Gombe A | DB8: 756653782 | DC8: nakijjobaharriet09@gmail.com | DD8: Yes | DE8: 100000 | DF8: IMG-20251112-WA0176-20_8_57.jpg | DG8: https://kf.kobotoolbox.org/api/v2/assets/a9dTHTe72X7zPceKxVtSxV/data/604370172/attachments/attR7YUZkRieSBhS3758ucGu/ | DH8: 676 | DI8: 10X Digital Economy Expression of interest Form | DJ8: 550 | DK8: 604370172 | DL8: cc141231-43f2-4fff-b593-2d30d8788b70 | DM8: 45973.769 | DP8: submitted_via_web | DR8: vCJgLk2yV8oivMfbcbCpCF | DT8: Stanbic Bank Incubator | DU8: Harrietcrafts | DV8: 604370172 | DW8: 1 | DX8: Nakijjoba | DY8: Yes | EL8: Gombe A | ES8: 1177 | ET8: 10X Digital Economy Expression of interest Form | EU8: 550 | EV8: 604370172 | EW8: cc141231-43f2-4fff-b593-2d30d8788b70 | EX8: 45973.769 | FA8: submitted_via_web | FC8: vCJgLk2yV8oivMfbcbCpCF | GK8: Unique | GL8: 29 | GM8: 29
A9: 0.0079074074 | B9: 45974 | C9: Stanbic Bank Incubator | D9: Salon | E9: We plaint hair | F9: No | H9: No | L9: No | N9: Central | O9: Wakiso | P9: Nsangi | Q9: Kikajjo | R9: fashion and design | T9: 1 | U9: 1 | V9: 1 | W9: 1 | X9: Crafts | Y9: Decorations | Z9: 11 | AA9: 25 | AB9: 604569648 | AC9: I use my own hands then after I sell them to get money | AD9: 60000 | AE9: No | AG9: No | AI9: 1000000 | AJ9: I want to be a business lady I want also to register my business so that its in are good path | AK9: Couse am confident | AL9: No | AN9: No | AP9: No | AR9: No | AT9: I need your help so that my business glow and wide | AU9: By announcement in our village | AV9: 5 - Very easy | AW9: Couse they was reasonble | AX9: Yes | BT9: 604569648 | BU9: 17e4008f-d739-4171-a069-fb9922c9af76 | BV9: 45974.199 | BY9: submitted_via_web | CA9: vCJgLk2yV8oivMfbcbCpCF | CC9: 556 | CF9: Stanbic Bank Incubator | CG9: Salon | CH9: 604569648 | CI9: 1 | CJ9: Gladys | CK9: Nalukenge | CL9: 38835 | CN9: Female | CO9: 100 | CP9: Ugandan | CQ9: No | CV9: Ugandan | CX9: Kampala | CY9: Nsangi | CZ9: Kikajjo | DA9: Katale | DB9: 747715389 | DC9: nalukengegladys42@gmail.cok | DD9: Yes | DE9: 500000 | DH9: 682 | DI9: 10X Digital Economy Expression of interest Form | DJ9: 556 | DK9: 604569648 | DL9: 17e4008f-d739-4171-a069-fb9922c9af76 | DM9: 45974.199 | DP9: submitted_via_web | DR9: vCJgLk2yV8oivMfbcbCpCF | DT9: Stanbic Bank Incubator | DU9: Salon | DV9: 604569648 | DW9: 1 | DX9: Nalukenge | DY9: No | DZ9: Gladys | EA9: 38835 | EB9: Female | EC9: Business owner | ED9: 500000 | EE9: No | EG9: Ugandan | EI9: Wakiso | EJ9: Nsangi | EK9: Kikajjo | EL9: Katale | EM9: 747715389 | EN9: nalukengegladys42@gmail.cok | EO9: S3 | EP9: CF06091107VCSL | ES9: 1183 | ET9: 10X Digital Economy Expression of interest Form | EU9: 556 | EV9: 604569648 | EW9: 17e4008f-d739-4171-a069-fb9922c9af76 | EX9: 45974.199 | FA9: submitted_via_web | FC9: vCJgLk2yV8oivMfbcbCpCF | FE9: Stanbic Bank Incubator | FF9: Salon | FG9: 604569648 | FH9: 1 | FI9: Gladys | FJ9: Nalukenge | FK9: 38835 | FL9: Female | FM9: Business owner | FN9: 200000 | FO9: No | FQ9: Ugandan | FS9: Wakiso | FT9: Nsangi | FU9: Kikajjo | FV9: Katale | FW9: 747715389 | FX9: nalukengegladys42l@gmail.cok | FY9: CF06091107VCSL | FZ9: 398 | GA9: 10X Digital Economy Expression of interest Form | GB9: 556 | GC9: 604569648 | GD9: 17e4008f-d739-4171-a069-fb9922c9af76 | GE9: 45974.199 | GH9: submitted_via_web | GJ9: vCJgLk2yV8oivMfbcbCpCF | GK9: Unique | GL9: 0 | GM9: 19
A10: 0.003775463 | B10: 45974 | C10: Stanbic Bank Incubator | D10: Simmy's nyam nyam snacks | E10: Cakes and cookies | F10: No | H10: No | L10: No | N10: Central | O10: Wakiso | P10: Nsangi | Q10: Nsangi | R10: trade and services | T10: 1 | U10: 1 | V10: 1 | W10: 0 | X10: Cakes: I sell the ones of 500 and the birthday cakes and cookies are for 500 | Y10: My business is solving the problem of reducing on the journey of people traveling to look for cakes in another environment | Z10: 1 | AA10: 0 | AB10: 604570098 | AC10: I sell the cakes to the shops and available customers and 1 dozen is for 5000 because each cake is for 500 | AD10: 0 | AE10: No | AG10: No | AI10: 5000000 | AJ10: To access digital tools in order to access more customers online | AK10: Because I give quality and sweet products and ensure customer's wants | AL10: No | AN10: No | AP10: No | AR10: No | AT10: I was much interested to learn more about running my business and using digital tools to run it | AU10: Program champion | AV10: 4 - Easy | AW10: Because I managed to answer all questions according to wat I do in real life | AX10: Yes | AZ10: They will help me to grow my business | BT10: 604570098 | BU10: 12cf702c-1c1f-4f42-9d3f-39d26abbff23 | BV10: 45974.2 | BY10: submitted_via_web | CA10: vCJgLk2yV8oivMfbcbCpCF | CC10: 557 | CF10: Stanbic Bank Incubator | CG10: Simmy's nyam nyam snacks | CH10: 604570098 | CI10: 1 | CJ10: Nakalawa | CK10: Patience | CL10: 38789 | CN10: Female | CO10: 100 | CP10: Ugandan | CQ10: No | CV10: Ugandan | CX10: Wakiso | CY10: Nsangi | CZ10: Nsangi | DA10: Nakasozi | DB10: 757227098 | DC10: patiencemujjuzi@gmail.com | DD10: Yes | DE10: 100000 | DH10: 683 | DI10: 10X Digital Economy Expression of interest Form | DJ10: 557 | DK10: 604570098 | DL10: 12cf702c-1c1f-4f42-9d3f-39d26abbff23 | DM10: 45974.2 | DP10: submitted_via_web | DR10: vCJgLk2yV8oivMfbcbCpCF | DT10: Stanbic Bank Incubator | DU10: Simmy's nyam nyam snacks | DV10: 604570098 | DW10: 1 | DX10: Nakalawa | DY10: Yes | EL10: Nakasozi | ES10: 1184 | ET10: 10X Digital Economy Expression of interest Form | EU10: 557 | EV10: 604570098 | EW10: 12cf702c-1c1f-4f42-9d3f-39d26abbff23 | EX10: 45974.2 | FA10: submitted_via_web | FC10: vCJgLk2yV8oivMfbcbCpCF | GK10: Unique | GL10: 19 | GM10: 19
A11: 0.013831019 | B11: 45974 | C11: Stanbic Bank Incubator | D11: Not yet | E11: Hairdressing | F11: No | H11: No | L11: No | N11: West | O11: Wakiso | P11: Kyengera | Q11: Kasenge | R11: Others | S11: Hairdressing | T11: 1 | U11: 1 | V11: 3 | W11: 0 | X11: Not yet | Y11: Keeping girl child away from poverty | Z11: 1 | AA11: 0 | AB11: 604833865 | AC11: Not yet | AD11: 50 | AE11: No | AG11: No | AI11: 2000000 | AJ11: Yes | AK11: I respect anyone | AL11: No | AN11: No | AP11: No | AR11: No | AT11: Nothing | AU11: It helps to uplift business | AV11: 4 - Easy | AW11: It's rare | AX11: Yes | AZ11: Ok | BT11: 604833865 | BU11: 09bbaaf3-e594-4323-9ee5-422dea85770f | BV11: 45974.448 | BY11: submitted_via_web | CA11: vCJgLk2yV8oivMfbcbCpCF | CC11: 575 | CF11: Stanbic Bank Incubator | CG11: Not yet | CH11: 604833865 | CI11: 1 | CJ11: Nansereko | CK11: Shamusa | CL11: 38947 | CN11: Female | CO11: 0 | CP11: Ugandan | CQ11: No | CV11: Ugandan | CX11: Wakiso | CY11: Nsangi | CZ11: Kasenge | DA11: Kikajjo | DB11: 746278715 | DC11: shamusanansereko@gmail.com | DD11: No | DH11: 703 | DI11: 10X Digital Economy Expression of interest Form | DJ11: 575 | DK11: 604833865 | DL11: 09bbaaf3-e594-4323-9ee5-422dea85770f | DM11: 45974.448 | DP11: submitted_via_web | DR11: vCJgLk2yV8oivMfbcbCpCF | DT11: Stanbic Bank Incubator | DU11: Not yet | DV11: 604833865 | DW11: 1 | DX11: Nansereko Shamusa | DY11: Yes | EL11: Kikajjo | ES11: 1204 | ET11: 10X Digital Economy Expression of interest Form | EU11: 575 | EV11: 604833865 | EW11: 09bbaaf3-e594-4323-9ee5-422dea85770f | EX11: 45974.448 | FA11: submitted_via_web | FC11: vCJgLk2yV8oivMfbcbCpCF | GK11: Unique | GL11: 19 | GM11: 19
A12: 0.014703704 | B12: 45974 | C12: Stanbic Bank Incubator | D12: Aggie's Best Cakes, Juice and Takeaway | E12: Cakes, daddies,Cookies, Doughnuts, Bread and bans and other bakery products | F12: No | H12: No | L12: No | N12: Central | O12: Wakiso | P12: Nsangi | Q12: Kasenge ward | R12: Others | S12: Bakery | T12: 1 | U12: 1 | V12: 1 | W12: 0 | X12: We provide Soft drinks, Juice in all types,cakes doughnuts, cookies, daddies, bread and bans, samosas and other bakery products | Y12: Limited customers because I work from home so I want to expand my business | Z12: 1 | AA12: 1 | AB12: 605258607 | AC12: It works supplying snacks for tea in the morning mostly. I fry and bake my foods and snacks, I walk looking for customers with my foods in buckets | AD12: 0 | AE12: No | AG12: No | AI12: 10000000 | AJ12: Financial skills and support | AK12: I have learnt more about business in the 10x program foundation course | AL12: Yes | AM12: My business can also give other young people employment under me | AN12: Yes | AO12: Teachers | AP12: Yes | AQ12: Teacher for business growth skills | AR12: No | AT12: I wanted to learn how to expand my business and build new ideas | AU12: Through Amodo Doreen | AV12: 5 - Very easy | AW12: Questions have all been about me and my business that I understood most | AX12: Yes | AZ12: Very fine | BT12: 605258607 | BU12: 7b2dbb0b-b45e-4712-a1fc-a23426c6d18f | BV12: 45974.771 | BY12: submitted_via_web | CA12: vCJgLk2yV8oivMfbcbCpCF | CC12: 589 | CF12: Stanbic Bank Incubator | CG12: Aggie's Best Cakes, Juice and Takeaway | CH12: 605258607 | CI12: 1 | CJ12: Tibiwa | CK12: Agnes | CL12: 37962 | CN12: Female | CO12: 90 | CP12: Uganda | CQ12: No | CV12: Ugandan | CX12: Wakiso | CY12: Nsangi | CZ12: Kasenge | DA12: Kinaawa | DB12: 746363643 | DC12: aggiemishello@gmail.com | DD12: Yes | DE12: 200000 | DH12: 717 | DI12: 10X Digital Economy Expression of interest Form | DJ12: 589 | DK12: 605258607 | DL12: 7b2dbb0b-b45e-4712-a1fc-a23426c6d18f | DM12: 45974.771 | DP12: submitted_via_web | DR12: vCJgLk2yV8oivMfbcbCpCF | DT12: Stanbic Bank Incubator | DU12: Aggie's Best Cakes, Juice and Takeaway | DV12: 605258607 | DW12: 1 | DX12: Tibiwa Agnes | DY12: Yes | EL12: Kinaawa | ES12: 1226 | ET12: 10X Digital Economy Expression of interest Form | EU12: 589 | EV12: 605258607 | EW12: 7b2dbb0b-b45e-4712-a1fc-a23426c6d18f | EX12: 45974.771 | FA12: submitted_via_web | FC12: vCJgLk2yV8oivMfbcbCpCF | GK12: Unique | GL12: 22 | GM12: 22
A13: 0.026737269 | B13: 45975 | C13: Stanbic Bank Incubator | D13: doesnt have | E13: baking and mobile money | F13: No | H13: No | L13: No | N13: Central | O13: Wakiso | P13: wakiso | Q13: Bukasa | R13: Light manufacturing | T13: 1 | U13: 1 | V13: 1 | W13: 1 | X13: cakes,breads ,cookies and mobile money | Y13: capital | Z13: 1 | AA13: 20 | AB13: 605484503 | AC13: it is working good | AD13: 0 | AE13: Yes | AF13: 1 | AG13: Yes | AH13: its good | AI13: 2000000 | AJ13: To serve uganda | AK13: its well with skills and quality | AL13: No | AN13: No | AP13: No | AR13: No | AT13: i was interested bse it teaches on bussines | AU13: from my friend | AV13: 2 - Difficult | AW13: Answering | AX13: Yes | BT13: 605484503 | BU13: 42cb7100-9107-456c-90e3-eff1c7ca0dac | BV13: 45975.251 | BY13: submitted_via_web | CA13: vCJgLk2yV8oivMfbcbCpCF | CC13: 599 | CF13: Stanbic Bank Incubator | CG13: doesnt have | CH13: 605484503 | CI13: 1 | CJ13: Mukyala | CK13: winfred | CL13: 36192 | CN13: Female | CO13: 100 | CP13: ugandan | CQ13: No | CV13: Ugandan | CX13: Wakiso | CY13: wakiso | CZ13: Bukasa | DA13: kigoma | DB13: 755387203 | DC13: twixwinnie21@gmail.com | DD13: Yes | DE13: 150000 | DH13: 727 | DI13: 10X Digital Economy Expression of interest Form | DJ13: 599 | DK13: 605484503 | DL13: 42cb7100-9107-456c-90e3-eff1c7ca0dac | DM13: 45975.251 | DP13: submitted_via_web | DR13: vCJgLk2yV8oivMfbcbCpCF | DT13: Stanbic Bank Incubator | DU13: doesnt have | DV13: 605484503 | DW13: 1 | DX13: Mukyala | DY13: Yes | EL13: kigoma | ES13: 1248 | ET13: 10X Digital Economy Expression of interest Form | EU13: 599 | EV13: 605484503 | EW13: 42cb7100-9107-456c-90e3-eff1c7ca0dac | EX13: 45975.251 | FA13: submitted_via_web | FC13: vCJgLk2yV8oivMfbcbCpCF | FE13: Stanbic Bank Incubator | FF13: doesnt have | FG13: 605484503 | FH13: 1 | FI13: mukyala | FJ13: winfred | FK13: 36192 | FL13: Female | FM13: selling to the customers | FN13: 150000 | FO13: No | FQ13: Ugandan | FS13: Wakiso | FT13: wakiso | FU13: Bukasa | FV13: kigoma | FW13: 755387203 | FX13: twixwinnie21@gmail.com | FY13: CF9900810EH9GA | FZ13: 408 | GA13: 10X Digital Economy Expression of interest Form | GB13: 599 | GC13: 605484503 | GD13: 42cb7100-9107-456c-90e3-eff1c7ca0dac | GE13: 45975.251 | GH13: submitted_via_web | GJ13: vCJgLk2yV8oivMfbcbCpCF | GK13: Unique | GL13: 27 | GM13: 27
A14: 0.021078704 | B14: 45976 | C14: Stanbic Bank Incubator | D14: Suma Mobile Money Services | E14: Easyload, deposit of cash, withdraw and phone accessories | F14: No | H14: No | J14: IMG-20251113-WA0073-16_44_12.jpg | K14: https://kf.kobotoolbox.org/api/v2/assets/a9dTHTe72X7zPceKxVtSxV/data/606622367/attachments/attJeAbFNwMWYpSuwCDEASqQ/ | L14: No | N14: Central | O14: Wakiso | P14: Nsangi | Q14: Kasenge ward | R14: trade and services | T14: 1 | U14: 1 | V14: 1 | W14: 0 | X14: We make it easy for people in the community to have their money in hard form instantly and even Making mobile services easier | Y14: Small scale that hinders potential customers | Z14: 1 | AA14: 1 | AB14: 606622367 | AC14: We withdraw and deposit money, sell easyload and making mobile services easier | AD14: 0 | AE14: No | AG14: Yes | AH14: It was about business skills and I gained mostly financial skills. I can now run my business successfully | AI14: 5000000 | AJ14: Giving out quality services | AK14: Because I have been taught more about business and understood the topics, and the high demand for mobile services in my community | AL14: Yes | AM14: I can employ other people | AN14: Yes | AO14: Teacher | AP14: Yes | AQ14: Teacher | AR14: No | AT14: I wanted to learn how to have a successful business | AU14: Howard Muhwezi | AV14: 4 - Easy | AW14: Most of them were questions about my business | AX14: Yes | AZ14: Thanks | BT14: 606622367 | BU14: 2f514c1d-cd44-4fa8-a95c-6022bf1d2d4e | BV14: 45976.672 | BY14: submitted_via_web | CA14: vCJgLk2yV8oivMfbcbCpCF | CC14: 708 | CF14: Stanbic Bank Incubator | CG14: Suma Mobile Money Services | CH14: 606622367 | CI14: 1 | CJ14: Nanyunja | CK14: Sumayiyah | CL14: 35616 | CN14: Female | CO14: 98 | CP14: Ugandan | CQ14: No | CV14: Ugandan | CX14: Wakiso | CY14: Nsangi | CZ14: Kasenge ward | DA14: Kyengera | DB14: 740522879 | DC14: sumayiyah58@gmail.com | DD14: Yes | DE14: 100000 | DF14: IMG-20251113-WA0073-18_10_32.jpg | DG14: https://kf.kobotoolbox.org/api/v2/assets/a9dTHTe72X7zPceKxVtSxV/data/606622367/attachments/attkTayWCHUd6sHZn7mwPpNA/ | DH14: 836 | DI14: 10X Digital Economy Expression of interest Form | DJ14: 708 | DK14: 606622367 | DL14: 2f514c1d-cd44-4fa8-a95c-6022bf1d2d4e | DM14: 45976.672 | DP14: submitted_via_web | DR14: vCJgLk2yV8oivMfbcbCpCF | DT14: Stanbic Bank Incubator | DU14: Suma Mobile Money Services | DV14: 606622367 | DW14: 1 | DX14: 1 | DY14: Yes | EL14: Kyengera | ES14: 1364 | ET14: 10X Digital Economy Expression of interest Form | EU14: 708 | EV14: 606622367 | EW14: 2f514c1d-cd44-4fa8-a95c-6022bf1d2d4e | EX14: 45976.672 | FA14: submitted_via_web | FC14: vCJgLk2yV8oivMfbcbCpCF | GK14: Unique | GL14: 22 | GM14: 22
A15: 0.0058657407 | B15: 45977 | C15: Stanbic Bank Incubator | D15: Sharifah Enterprises Ltd | E15: We deal in charcoal and grocery, providing basics to the community making life more easier | F15: No | H15: No | J15: IMG-20251113-WA0034-2_17_40.jpg | K15: https://kf.kobotoolbox.org/api/v2/assets/a9dTHTe72X7zPceKxVtSxV/data/606771268/attachments/attQdoZHKuXsjEJk3PeyjJSx/ | L15: No | N15: Central | O15: Wakiso | P15: Nsangi | Q15: Kasenge ward | R15: trade and services | T15: 1 | U15: 1 | V15: 1 | W15: 0 | X15: We deal in charcoal selling and grocery | Y15: Insufficient capital | Z15: 1 | AA15: 1 | AB15: 606771268 | AC15: Dealers in charcoal selling and grocery, I make money through buying charcoal from nearby villages and get some little profits due to little capital, get groceries from the market and have 5% as profits. I sell the products at a low price due to the place am in. | AD15: 0 | AE15: No | AG15: Yes | AH15: I learnt basics on how to manage personal and business finances and Mr. Bernard was the teacher | AI15: 3000000 | AJ15: Expansion of my business | AK15: Because am working and I want to expand my business | AL15: Yes | AM15: After expanding my business, I want to also support other youth to get employed by giving them jobs | AN15: Yes | AO15: Teacher | AP15: Yes | AQ15: Business expert | AR15: No | AT15: I want to learn how to succeed in my business | AU15: From Howard Muhwezi | AV15: 4 - Easy | AW15: All the questions where about me and my business that 8 understood more | AX15: Yes | AZ15: Thanks for the program | BT15: 606771268 | BU15: 469f176e-2d69-435c-a015-7095f1229719 | BV15: 45976.983 | BY15: submitted_via_web | CA15: vCJgLk2yV8oivMfbcbCpCF | CC15: 718 | CF15: Stanbic Bank Incubator | CG15: Sharifah Enterprises Ltd | CH15: 606771268 | CI15: 1 | CJ15: Nabaata | CK15: Sharifah | CL15: 33691 | CN15: Female | CO15: 90 | CP15: Ugandan | CQ15: No | CV15: Ugandan | CX15: Wakiso | CY15: Nsangi | CZ15: Kasenge ward | DA15: Kazinga | DB15: 709734971 | DC15: nabattas80@gmail.com | DD15: Yes | DE15: 300000 | DF15: IMG-20251113-WA0034-2_21_55.jpg | DG15: https://kf.kobotoolbox.org/api/v2/assets/a9dTHTe72X7zPceKxVtSxV/data/606771268/attachments/attVnmHs97retdqm7Wny5qyE/ | DH15: 846 | DI15: 10X Digital Economy Expression of interest Form | DJ15: 718 | DK15: 606771268 | DL15: 469f176e-2d69-435c-a015-7095f1229719 | DM15: 45976.983 | DP15: submitted_via_web | DR15: vCJgLk2yV8oivMfbcbCpCF | DT15: Stanbic Bank Incubator | DU15: Sharifah Enterprises Ltd | DV15: 606771268 | DW15: 1 | DX15: Nabaata | DY15: Yes | EL15: Kazinga | ES15: 1375 | ET15: 10X Digital Economy Expression of interest Form | EU15: 718 | EV15: 606771268 | EW15: 469f176e-2d69-435c-a015-7095f1229719 | EX15: 45976.983 | FA15: submitted_via_web | FC15: vCJgLk2yV8oivMfbcbCpCF | GK15: Unique | GL15: 33 | GM15: 33
A16: 0.024893519 | B16: 45977 | C16: Stanbic Bank Incubator | D16: Sadress Poultry Farmers | E16: Dealers in Poultry of all kinds, like broilers, croilers, layers and eggs suppliers | F16: No | H16: No | J16: IMG-20251115-WA0005-2_52_22.jpg | K16: https://kf.kobotoolbox.org/api/v2/assets/a9dTHTe72X7zPceKxVtSxV/data/606777477/attachments/attWUL8HR7tj63GKQ4qxeUpN/ | L16: No | N16: Central | O16: Wakiso | P16: Nsangi | Q16: Kasenge ward | R16: Agriculture | T16: 1 | U16: 1 | V16: 1 | W16: 0 | X16: Dealers in all kinds of Poultry, broilers, croilers,layers and eggs supplies | Y16: Small scale of land and insufficient funds | Z16: 1 | AA16: 1 | AB16: 606777477 | AC16: We deal supply of broilers, croilers and eggs supply. I supply retail shop and earn income | AD16: 0 | AE16: No | AG16: Yes | AH16: I was all about business skills for success and I learnt more about business growth | AI16: 5000000 | AJ16: Giving out jobs to others and teaching them what I learnt in 10x that led to my success | AK16: Because it's the backbone of Uganda | AL16: Yes | AM16: My business promotes health and improves on people's lives | AN16: Yes | AO16: Teacher | AP16: Yes | AQ16: Business expert | AR16: No | AT16: I wanted to expand my business | AU16: Through Amodo Doreen | AV16: 4 - Easy | AW16: Because it was all about business | AX16: Yes | AZ16: Thanks | BT16: 606777477 | BU16: a00b5db3-c1d2-4c8b-a179-ffd717547062 | BV16: 45977.012 | BY16: submitted_via_web | CA16: vCJgLk2yV8oivMfbcbCpCF | CC16: 719 | CF16: Stanbic Bank Incubator | CG16: Sadress Poultry Farmers | CH16: 606777477 | CI16: 1 | CJ16: Kyabiere | CK16: Sadress | CL16: 34030 | CN16: Female | CO16: 80 | CP16: Ugandan | CQ16: No | CV16: Ugandan | CX16: Wakiso | CY16: Nsangi | CZ16: Kasenge ward | DA16: Kazinga | DB16: 776816316 | DC16: sadresskyabiere@gmail.com | DD16: Yes | DE16: 100000 | DF16: IMG-20251115-WA0005-2_52_22-2_57_20.jpg | DG16: https://kf.kobotoolbox.org/api/v2/assets/a9dTHTe72X7zPceKxVtSxV/data/606777477/attachments/att3WZM7pQPv2Vws2huHVEE9/ | DH16: 847 | DI16: 10X Digital Economy Expression of interest Form | DJ16: 719 | DK16: 606777477 | DL16: a00b5db3-c1d2-4c8b-a179-ffd717547062 | DM16: 45977.012 | DP16: submitted_via_web | DR16: vCJgLk2yV8oivMfbcbCpCF | DT16: Stanbic Bank Incubator | DU16: Sadress Poultry Farmers | DV16: 606777477 | DW16: 1 | DX16: Kyabiere | DY16: Yes | EL16: Kazinga | ES16: 1376 | ET16: 10X Digital Economy Expression of interest Form | EU16: 719 | EV16: 606777477 | EW16: a00b5db3-c1d2-4c8b-a179-ffd717547062 | EX16: 45977.012 | FA16: submitted_via_web | FC16: vCJgLk2yV8oivMfbcbCpCF | GK16: Unique | GL16: 32 | GM16: 32
A17: 0.018630787 | B17: 45978 | C17: Stanbic Bank Incubator | D17: Carol Retail shop | E17: We deal in all kinds mostly common use basics like soap, sugar, dry food Vaselines etc | F17: No | H17: No | L17: No | N17: Central | O17: Wakiso | P17: Nsangi | Q17: Kasenge ward | R17: trade and services | T17: 1 | U17: 1 | V17: 1 | W17: 0 | X17: We offer basic needs to the community nearer including sugar, dry food, soap etc | Y17: Insufficient capital | Z17: 1 | AA17: 1 | AB17: 607266161 | AC17: I buy and sell products have some profits and contine running my business | AD17: 0 | AE17: No | AG17: Yes | AH17: I learnt more about business skills and I can now generate new ideas | AI17: 3000000 | AJ17: I want to keep my business grow and developing mu country by giving revenue | AK17: Because am in a still growing community | AL17: Yes | AM17: I want to register my business and learn more about it | AN17: No | AP17: Yes | AQ17: Teacher | AR17: No | AT17: My businesses have been failling | AU17: Kayaga Patricia | AV17: 4 - Easy | AW17: All was about business | AX17: Yes | AZ17: Thank you | BT17: 607266161 | BU17: e1b17516-b9cd-4975-a9f8-6b62b3dd845e | BV17: 45978.003 | BY17: submitted_via_web | CA17: vCJgLk2yV8oivMfbcbCpCF | CC17: 736 | CF17: Stanbic Bank Incubator | CG17: Carol Retail shop | CH17: 607266161 | CI17: 1 | CJ17: Nansubuga | CK17: Carol | CL17: 37538 | CN17: Female | CO17: 90 | CP17: Ugandan | CQ17: No | CV17: Ugandan | CX17: Wakiso | CY17: Nsangi | CZ17: Kasenge ward | DA17: Kikajjo | DB17: 708040037 | DC17: nansubugacarol@gmail.com | DD17: Yes | DE17: 200000 | DF17: IMG-20251114-WA0056-2_45_30.jpg | DG17: https://kf.kobotoolbox.org/api/v2/assets/a9dTHTe72X7zPceKxVtSxV/data/607266161/attachments/attFD78cMZHgYJAtge7Es8Cu/ | DH17: 864 | DI17: 10X Digital Economy Expression of interest Form | DJ17: 736 | DK17: 607266161 | DL17: e1b17516-b9cd-4975-a9f8-6b62b3dd845e | DM17: 45978.003 | DP17: submitted_via_web | DR17: vCJgLk2yV8oivMfbcbCpCF | DT17: Stanbic Bank Incubator | DU17: Carol Retail shop | DV17: 607266161 | DW17: 1 | DX17: Nansubuga | DY17: Yes | EL17: Kikajjo | ES17: 1393 | ET17: 10X Digital Economy Expression of interest Form | EU17: 736 | EV17: 607266161 | EW17: e1b17516-b9cd-4975-a9f8-6b62b3dd845e | EX17: 45978.003 | FA17: submitted_via_web | FC17: vCJgLk2yV8oivMfbcbCpCF | GK17: Unique | GL17: 23 | GM17: 23
A18: 0.0031064815 | B18: 45978 | C18: Stanbic Bank Incubator | D18: J and J Beauty Salon | E18: We offer braids styles in all kinds | F18: No | H18: No | L18: No | N18: Central | O18: Wakiso | P18: Nsangi | Q18: Kasenge ward | R18: fashion and design | T18: 1 | U18: 1 | V18: 1 | W18: 0 | X18: We offer braid styles in all kinds. | Y18: I work from home, I want to have a place for work | Z18: 1 | AA18: 1 | AB18: 607270081 | AC18: I get customers and plait their hair, get money for profits helping in the on going of the business | AD18: 0 | AE18: No | AG18: Yes | AH18: We learnt about business ethics | AI18: 4000000 | AJ18: When my business is successful, k can also teach people my professions | AK18: Because my business supports young people which 10x is aiming at | AL18: Yes | AM18: I want to register my business | AN18: Yes | AO18: Teacher | AP18: Yes | AQ18: Teacher and student | AR18: No | AT18: I wanted to learn business growth | AU18: Amodo Doreen | AV18: 4 - Easy | AW18: Business is the topic | AX18: Yes | AZ18: Thanks | BT18: 607270081 | BU18: a80d220b-78d3-40aa-ba5e-17c2f445eb51 | BV18: 45978.017 | BY18: submitted_via_web | CA18: vCJgLk2yV8oivMfbcbCpCF | CC18: 737 | CF18: Stanbic Bank Incubator | CG18: J and J Beauty Salon | CH18: 607270081 | CI18: 1 | CJ18: Nalugwa | CK18: Juliet | CL18: 36993 | CN18: Female | CO18: 94 | CP18: Ugandan | CQ18: No | CV18: Ugandan | CX18: Wakiso | CY18: Nsangi | CZ18: Kasenge ward | DA18: Kazinga | DB18: 761316517 | DC18: julietnalugwa818@gmail.com | DD18: Yes | DE18: 200000 | DF18: IMG-20251113-WA0007-3_14_24.jpg | DG18: https://kf.kobotoolbox.org/api/v2/assets/a9dTHTe72X7zPceKxVtSxV/data/607270081/attachments/attCcsBGVcXbSkzSqaM7sCrk/ | DH18: 865 | DI18: 10X Digital Economy Expression of interest Form | DJ18: 737 | DK18: 607270081 | DL18: a80d220b-78d3-40aa-ba5e-17c2f445eb51 | DM18: 45978.017 | DP18: submitted_via_web | DR18: vCJgLk2yV8oivMfbcbCpCF | DT18: Stanbic Bank Incubator | DU18: J and J Beauty Salon | DV18: 607270081 | DW18: 1 | DX18: Nalugwa | DY18: Yes | EL18: Kazinga | ES18: 1394 | ET18: 10X Digital Economy Expression of interest Form | EU18: 737 | EV18: 607270081 | EW18: a80d220b-78d3-40aa-ba5e-17c2f445eb51 | EX18: 45978.017 | FA18: submitted_via_web | FC18: vCJgLk2yV8oivMfbcbCpCF | GK18: Unique | GL18: 24 | GM18: 24
A19: 0.025082176 | B19: 45978 | C19: Stanbic Bank Incubator | D19: Sylvia enterprise | E19: Dealing in Scholastic materials, mobile money, and tailoring | F19: No | H19: No | L19: No | N19: Central | O19: Wakiso | P19: Ndejje | Q19: Ndejje | R19: fashion and design | T19: 1 | U19: 1 | V19: 1 | W19: 0 | X19: Books, airtime,deposit and withdraw | Y19: Lack of enough capital | Z19: 1 | AA19: 1 | AB19: 607591148 | AC19: By sale of books, and repairing people's clothes | AD19: 0 | AE19: No | AG19: No | AI19: 5000000 | AJ19: I expect has business to grow by 70 percent by the end of next year if I get more capital. | AK19: Because it operates in highly populated area. | AL19: No | AN19: No | AP19: No | AR19: No | AT19: To acquire more knowledge of how to operate a business. | AU19: It's a program that provides knowledge about operating a business. | AV19: 4 - Easy | AW19: Because these are the things we move in in our day today life | AX19: Yes | AZ19: I thank the 10x program for this initiative. | BT19: 607591148 | BU19: b70d05b7-8837-4aae-98aa-a8c3f6d76b95 | BV19: 45978.426 | BY19: submitted_via_web | CA19: vCJgLk2yV8oivMfbcbCpCF | CC19: 739 | CF19: Stanbic Bank Incubator | CG19: Sylvia enterprise | CH19: 607591148 | CI19: 1 | CJ19: Sylivia | CK19: Namugambe | CL19: 32680 | CN19: Female | CO19: 100 | CP19: Ugandan | CQ19: No | CV19: Ugandan | CX19: Wakiso | CY19: Ndejje | CZ19: Ndejje | DA19: Bongole | DB19: 755910515 | DC19: sylivianamugambe497@gmail.com | DD19: Yes | DE19: 50000 | DF19: IMG_20251116_232749_013~2-12_50_51.jpg | DG19: https://kf.kobotoolbox.org/api/v2/assets/a9dTHTe72X7zPceKxVtSxV/data/607591148/attachments/attSCndjS2Mt3vtjU6N7MEyE/ | DH19: 867 | DI19: 10X Digital Economy Expression of interest Form | DJ19: 739 | DK19: 607591148 | DL19: b70d05b7-8837-4aae-98aa-a8c3f6d76b95 | DM19: 45978.426 | DP19: submitted_via_web | DR19: vCJgLk2yV8oivMfbcbCpCF | DT19: Stanbic Bank Incubator | DU19: Sylvia enterprise | DV19: 607591148 | DW19: 1 | DX19: Sylivia | DY19: Yes | EL19: Bongole | ES19: 1396 | ET19: 10X Digital Economy Expression of interest Form | EU19: 739 | EV19: 607591148 | EW19: b70d05b7-8837-4aae-98aa-a8c3f6d76b95 | EX19: 45978.426 | FA19: submitted_via_web | FC19: vCJgLk2yV8oivMfbcbCpCF | GK19: Unique | GL19: 0
A20: 0.036561343 | B20: 45978 | C20: Stanbic Bank Incubator | D20: Godhen collections | E20: A boutique | F20: No | H20: No | L20: No | N20: Central | O20: Wakiso | P20: Kajjansi | Q20: Nsaggu | R20: fashion and design | T20: 1 | U20: 1 | V20: 1 | W20: 0 | X20: We sell clothes | Y20: We give wears | Z20: 1 | AA20: 2 | AB20: 607840757 | AC20: I charge between 20k and 50k | AD20: 0 | AE20: Yes | AF20: 1 | AG20: No | AI20: 5000000 | AJ20: To make the first shop bigger and to facilitate the branch | AK20: It's in the center of the town and we advertise | AL20: Yes | AM20: I need a help to register my business | AN20: No | AP20: No | AR20: No | AT20: To get more knowledge about business | AU20: By a friend | AV20: 4 - Easy | AW20: I know the language | AX20: Yes | AZ20: Thank you | BT20: 607840757 | BU20: 93afd76a-5b28-466e-9ac7-f774579a0885 | BV20: 45978.579 | BY20: submitted_via_web | CA20: vCJgLk2yV8oivMfbcbCpCF | CC20: 745 | CF20: Stanbic Bank Incubator | CG20: Godhen collections | CH20: 607840757 | CI20: 1 | CJ20: NKWANGA | CK20: LYDIA | CL20: 31747 | CN20: Female | CO20: 100 | CP20: Ugandan | CQ20: No | CV20: Ugandan | CX20: Wakiso | CY20: Kajjansi | CZ20: Nsaggu | DA20: Nsaggu | DB20: 789538005 | DC20: zaweddelydia711@gmail.com | DD20: No | DF20: 17633856835095840836843592302337-16_21_58.jpg | DG20: https://kf.kobotoolbox.org/api/v2/assets/a9dTHTe72X7zPceKxVtSxV/data/607840757/attachments/att52FToiZfPZLMWATWuedtN/ | DH20: 874 | DI20: 10X Digital Economy Expression of interest Form | DJ20: 745 | DK20: 607840757 | DL20: 93afd76a-5b28-466e-9ac7-f774579a0885 | DM20: 45978.579 | DP20: submitted_via_web | DR20: vCJgLk2yV8oivMfbcbCpCF | DT20: Stanbic Bank Incubator | DU20: Godhen collections | DV20: 607840757 | DW20: 1 | DX20: Nkwanga Lydia | DY20: Yes | EL20: Nsaggu | ES20: 1406 | ET20: 10X Digital Economy Expression of interest Form | EU20: 745 | EV20: 607840757 | EW20: 93afd76a-5b28-466e-9ac7-f774579a0885 | EX20: 45978.579 | FA20: submitted_via_web | FC20: vCJgLk2yV8oivMfbcbCpCF | GK20: Unique | GL20: 39 | GM20: 39
